import {
  throwError,
  throwCustomError,
  resolveValue,
  MyAwesomeError,
  rejectCustomError,
} from './index';

describe('resolveValue', () => {
  test('should resolve provided value', async () => {
    const value = 42;
    await expect(resolveValue(value)).resolves.toBe(value);
  });
});

describe('throwError', () => {
  test('should throw error with provided message', () => {
    const errorMessage = 'Ooo no! An error occured!';
    expect(() => throwError(errorMessage)).toThrowError(errorMessage);
  });

  test('should throw error with default message if message is not provided', () => {
    expect(() => throwError()).toThrowError('Oops!');
  });
});

describe('throwCustomError', () => {
  test('should throw custom error', () => {
    expect(() => throwCustomError()).toThrowError(MyAwesomeError);
  });
});

describe('rejectCustomError', () => {
  test('should reject custom error', async () => {
    await expect(() => rejectCustomError()).rejects.toThrowError(
      MyAwesomeError,
    );
  });
});
